Workbook

Sheet 간편계산기
A1: 간편 계산기 · 재학생 수만 넣으면 예상 교사확보율이 나옵니다
A2: 노란 칸에 예상 재학생 수만 넣으세요. 나머지는 자동 계산됩니다. 처음에는 2025년 실적이 들어 있어 2025 공시값과 같은 결과가 나옵니다. | J2: =기초자료_2025!$E$16 | K2: 교사 인정면적 2025(㎡)
A3: ="※ 건물(교사) 인정면적은 2025년 실적 "&TEXT($J$2,"#,##0")&"㎡ 그대로라고 가정합니다. 신축·철거를 반영하거나 연도별로 예측하려면 '입력' 시트를 쓰세요." | J3: =기초자료_2025!$C$39 | K3: 재학생 기준면적 2025(㎡)
J4: =SUM(기초자료_2025!$G$25:$G$27) | K4: 재학생 수 2025(명)
A5: 방법 ① 전체 재학생 수만 넣기 — 가장 간단 | J5: =J3/J4 | K5: 1인당 평균 기준면적(㎡) = J3/J4
A6: 예상 재학생 수 (명) ✎ 입력 | E6: 예상 교사확보율 | G6: 판정 | J6: =J2/J3*100 | K6: 재학생기준 확보율 2025(%)
A7: =$J$4 | D7: ▶ | E7: =IF(AND(ISNUMBER(A7),A7>0),$J$2/(A7*$J$5)*100,"") | G7: =IF(NOT(ISNUMBER(E7)),"",IF(E7<100,"미달",IF(E7<사용안내!$C$27,"주의","적정")))
A9: =IF(E7="","재학생 수를 0보다 큰 숫자로 넣어 주세요.","재학생이 "&TEXT(A7,"#,##0")&"명이면 예상 교사확보율은 "&TEXT(E7,"0.0")&"%입니다. (2025년 실적 "&TEXT($J$6,"0.0")&"%보다 "&TEXT(ROUND(E7-$J$6,1),"+0.0;-0.0;0.0")&"%p, "&IF(E7>=100,"법정 기준 100% 충족","법정 기준 100% 미달")&")")
A10: =IF(E7="","","계산: 교사 인정면적 "&TEXT($J$2,"#,##0")&"㎡ ÷ (재학생 "&TEXT(A7,"#,##0")&"명 × 1인당 평균 "&TEXT($J$5,"0.00")&"㎡) × 100 = "&TEXT(E7,"0.0")&"%")
A11: ="※ 1인당 평균 "&TEXT($J$5,"0.00")&"㎡는 2025년 계열 구성(인문사회 1인당 12㎡, 자연과학·공학·예체능 14㎡)이 그대로 유지된다고 보고 계산한 값입니다. 계열 구성이 크게 바뀔 것 같으면 아래 방법 ②를 쓰세요."
A13: 방법 ② 계열별 재학생 수 넣기 — 더 정확 (천안·서울, 학부·대학원 모두 합친 인원)
A14: 계열 | B14: 1인당 기준면적 | C14: 2025 실적 (참고) | D14: 예상 재학생 수 ✎ 입력 | E14: 필요 기준면적(㎡) = 인원 × 1인당 | G14: 예상 교사확보율
A15: 인문사회 | B15: 12 | C15: =SUM(기초자료_2025!C25:C27) | D15: =C15 | E15: =B15*D15 | G15: =IF(E19>0,$J$2/E19*100,"")
A16: 자연과학 | B16: 14 | C16: =SUM(기초자료_2025!D25:D27) | D16: =C16 | E16: =B16*D16
A17: 공학 | B17: 14 | C17: =SUM(기초자료_2025!E25:E27) | D17: =C17 | E17: =B17*D17 | G17: 판정
A18: 예체능 | B18: 14 | C18: =SUM(기초자료_2025!F25:F27) | D18: =C18 | E18: =B18*D18 | G18: =IF(NOT(ISNUMBER(G15)),"",IF(G15<100,"미달",IF(G15<사용안내!$C$27,"주의","적정")))
A19: 합계 | C19: =SUM(C15:C18) | D19: =SUM(D15:D18) | E19: =SUM(E15:E18)
A20: =IF(G15="","재학생 수를 입력해 주세요.","재학생 "&TEXT(D19,"#,##0")&"명(인문사회 "&TEXT(D15,"#,##0")&" · 자연과학 "&TEXT(D16,"#,##0")&" · 공학 "&TEXT(D17,"#,##0")&" · 예체능 "&TEXT(D18,"#,##0")&")이면 예상 교사확보율은 "&TEXT(G15,"0.0")&"%입니다. (2025년 실적 대비 "&TEXT(ROUND(G15-$J$6,1),"+0.0;-0.0;0.0")&"%p)")
A21: =IF(G15="","","계산: 교사 인정면적 "&TEXT($J$2,"#,##0")&"㎡ ÷ 필요 기준면적 합계 "&TEXT(E19,"#,##0")&"㎡ × 100 = "&TEXT(G15,"0.0")&"%")
A23: 한눈에 보는 표 — 전체 재학생 수별 예상 교사확보율 (방법 ① 기준)
A24: ="▶ 재학생이 "&TEXT(ROUNDDOWN($J$2/$J$5,0),"#,##0")&"명 이하면 법정 기준(100%) 충족, "&TEXT(ROUNDDOWN($J$2/($J$5*사용안내!$C$27/100),0),"#,##0")&"명 이하면 주의 기준("&사용안내!$C$27&"%) 이상입니다."
A25: 재학생 수(명) | B25: 예상 확보율 | C25: 2025 실적 대비 | D25: 판정
A26: 11000 | B26: =$J$2/(A26*$J$5)*100 | C26: =ROUND(B26-$J$6,1) | D26: =IF(NOT(ISNUMBER(B26)),"",IF(B26<100,"미달",IF(B26<사용안내!$C$27,"주의","적정")))
A27: 11500 | B27: =$J$2/(A27*$J$5)*100 | C27: =ROUND(B27-$J$6,1) | D27: =IF(NOT(ISNUMBER(B27)),"",IF(B27<100,"미달",IF(B27<사용안내!$C$27,"주의","적정")))
A28: 12000 | B28: =$J$2/(A28*$J$5)*100 | C28: =ROUND(B28-$J$6,1) | D28: =IF(NOT(ISNUMBER(B28)),"",IF(B28<100,"미달",IF(B28<사용안내!$C$27,"주의","적정")))
A29: 12500 | B29: =$J$2/(A29*$J$5)*100 | C29: =ROUND(B29-$J$6,1) | D29: =IF(NOT(ISNUMBER(B29)),"",IF(B29<100,"미달",IF(B29<사용안내!$C$27,"주의","적정")))
A30: 13000 | B30: =$J$2/(A30*$J$5)*100 | C30: =ROUND(B30-$J$6,1) | D30: =IF(NOT(ISNUMBER(B30)),"",IF(B30<100,"미달",IF(B30<사용안내!$C$27,"주의","적정")))
A31: 13500 | B31: =$J$2/(A31*$J$5)*100 | C31: =ROUND(B31-$J$6,1) | D31: =IF(NOT(ISNUMBER(B31)),"",IF(B31<100,"미달",IF(B31<사용안내!$C$27,"주의","적정")))
A32: 14000 | B32: =$J$2/(A32*$J$5)*100 | C32: =ROUND(B32-$J$6,1) | D32: =IF(NOT(ISNUMBER(B32)),"",IF(B32<100,"미달",IF(B32<사용안내!$C$27,"주의","적정")))
A33: 14500 | B33: =$J$2/(A33*$J$5)*100 | C33: =ROUND(B33-$J$6,1) | D33: =IF(NOT(ISNUMBER(B33)),"",IF(B33<100,"미달",IF(B33<사용안내!$C$27,"주의","적정")))
A34: 15000 | B34: =$J$2/(A34*$J$5)*100 | C34: =ROUND(B34-$J$6,1) | D34: =IF(NOT(ISNUMBER(B34)),"",IF(B34<100,"미달",IF(B34<사용안내!$C$27,"주의","적정")))
A35: 15500 | B35: =$J$2/(A35*$J$5)*100 | C35: =ROUND(B35-$J$6,1) | D35: =IF(NOT(ISNUMBER(B35)),"",IF(B35<100,"미달",IF(B35<사용안내!$C$27,"주의","적정")))
A36: 16000 | B36: =$J$2/(A36*$J$5)*100 | C36: =ROUND(B36-$J$6,1) | D36: =IF(NOT(ISNUMBER(B36)),"",IF(B36<100,"미달",IF(B36<사용안내!$C$27,"주의","적정")))
A37: 16500 | B37: =$J$2/(A37*$J$5)*100 | C37: =ROUND(B37-$J$6,1) | D37: =IF(NOT(ISNUMBER(B37)),"",IF(B37<100,"미달",IF(B37<사용안내!$C$27,"주의","적정")))
... A40: 18000 | B40: =$J$2/(A40*$J$5)*100 | C40: =ROUND(B40-$J$6,1) | D40: =IF(NOT(ISNUMBER(B40)),"",IF(B40<100,"미달",IF(B40<사용안내!$C$27,"주의","적정")))
A42: ※ 판정: 100% 미만 = 미달, 100% 이상 ~ 주의 기준 미만 = 주의, 그 이상 = 적정 (주의 기준은 사용안내 시트에서 변경). 이 계산기는 재학생기준 확보율만 계산합니다. 입학정원기준 확보율은 재학생 수와 관계없이 입학정원·면적이 바뀔 때만 변합니다.

Sheet 사용안내
A1: 교사(校舍)시설 확보율 예측 시뮬레이션 — 사용안내
A2: 2025 시설현황 집계표와 2025 정보공시(14-라)를 바탕으로, 재학생 수가 바뀌면 교사확보율이 어떻게 변하는지 미리 계산해 보는 파일입니다.
A4: 이렇게 쓰세요 (3단계) ※ 재학생 수만으로 빠르게 보려면 첫 번째 '간편계산기' 시트만 쓰면 됩니다
A5: 1 | B5: 입력 시트 | D5: 노란 칸에 연도별 예상 재학생 수를 넣습니다. 정원 조정이나 건물 신축·철거가 있으면 STEP 2·3도 고칩니다.
A6: 2 | B6: 결과요약 시트 | D6: 맨 위 '조회 연도'를 고르면 그 해 확보율·여유면적·판정과 쉬운 설명 문장이 나옵니다. 아래 표와 그래프로 연도별 흐름을 봅니다.
A7: 3 | B7: 민감도 시트 | D7: 재학생 증감별 확보율 변화, 목표 확보율을 지키는 최대 증가 인원, 계열을 섞은 시나리오 계산을 단계별로 확인합니다.
A9: 칸 색깔의 의미
B10: 노란 칸 | D10: 직접 고치는 입력 칸
B11: 회색 칸 | D11: 2025 실적(기초자료와 연결, 수정 불필요)
B12: 흰 칸 | D12: 자동 계산 칸 (수정 금지)
A14: 용어 쉽게 풀기
A15: 교사확보율 | D15: 확보율 계산에 인정되는 건물 면적 ÷ 법정 기준면적 × 100. 100% 이상이면 기준 충족
A16: 재학생 기준면적(B) | D16: 계열별 재학생 수 × 1인당 기준면적(인문사회 12㎡, 자연과학·공학·예체능 14㎡)
A17: 입학정원 기준면적(A) | D17: 계열별 입학정원 × 수업연한 × 1인당 기준면적. 재학생 수가 바뀌어도 변하지 않음
A18: 교사 인정면적(C+D+E) | D18: 기본시설(강의실·실험실·도서관 등) + 지원시설(기숙사·강당 등) + 연구시설. 부속·기타시설은 제외
A19: 여유 면적 | D19: 교사 인정면적 − 재학생 기준면적. 이 면적을 1인당 기준면적으로 나누면 더 받을 수 있는 재학생 수
A20: 법정 의무 기준 | D20: 재학생이 입학정원보다 적으면 재학생 기준면적 이상, 그렇지 않으면 입학정원 기준면적 이상 보유해야 함
A22: 실적 현황 | D22: 2024 실적 | E22: 2025 실적 | F22: 변화
A23: 재학생기준 확보율 | D23: =결과요약!F17 | E23: =결과요약!F18 | F23: =E23-D23
A24: 입학정원기준 확보율 | D24: =결과요약!G17 | E24: =결과요약!G18 | F24: =E24-D24
A25: 여유 면적(㎡) | D25: =결과요약!J17 | E25: =결과요약!J18 | F25: =E25-D25
A26: 설정
A27: '주의' 판정 기준(%) | C27: 110 | D27: 확보율이 100% 이상이지만 이 값보다 낮으면 '주의'로 표시합니다. 내부 관리용 임의 기준이므로 필요에 맞게 바꾸세요.

Sheet 입력
A1: 입력 · 노란 칸만 고치면 결과요약이 자동으로 바뀝니다
A2: 2026년 이후 칸에는 전년도 값이 미리 들어 있습니다. 바뀔 것으로 예상되는 칸만 새 숫자로 덮어쓰세요. 예) 2027년 천안 대학원 공학 재학생 229 → 300명 예상이면 그 칸에 300 입력. 2024·2025는 실적(회색)이라 고치지 않습니다.
A4: 캠퍼스 | B4: 과정 | C4: 계열 | D4: 1인당 기준면적(㎡) | F4: 2024 실적 | G4: 2025 실적 | H4: 2026 예측 | I4: 2027 예측 | J4: 2028 예측 | K4: 2029 예측 | L4: 2030 예측
A6: STEP 1. 재학생 수 (명) — 매년 4월 1일 기준 예상 인원 ★ 가장 중요
A7: 정원내+정원외 포함 / 계약학과, 특성화고 재직자 특별전형, 학사학위취득유예생은 빼고 입력. 대학원은 주간 재학생.
A8: 본교(천안) | B8: 학부 | C8: 인문사회 | D8: 12 | F8: =기초자료_2024!C25 | G8: =기초자료_2025!C25 | H8: =G8 | I8: =H8 | J8: =I8 | K8: =J8 | L8: =K8
C9: 자연과학 | D9: 14 | F9: =기초자료_2024!D25 | G9: =기초자료_2025!D25 | H9: =G9 | I9: =H9 | J9: =I9 | K9: =J9 | L9: =K9
C10: 공학 | D10: 14 | F10: =기초자료_2024!E25 | G10: =기초자료_2025!E25 | H10: =G10 | I10: =H10 | J10: =I10 | K10: =J10 | L10: =K10
C11: 예체능 | D11: 14 | F11: =기초자료_2024!F25 | G11: =기초자료_2025!F25 | H11: =G11 | I11: =H11 | J11: =I11 | K11: =J11 | L11: =K11
A12: 본교(천안) 학부 소계 | F12: =SUM(F8:F11) | G12: =SUM(G8:G11) | H12: =SUM(H8:H11) | I12: =SUM(I8:I11) | J12: =SUM(J8:J11) | K12: =SUM(K8:K11) | L12: =SUM(L8:L11)
A13: 본교(천안) | B13: 대학원 | C13: 인문사회 | D13: 12 | F13: =기초자료_2024!C26 | G13: =기초자료_2025!C26 | H13: =G13 | I13: =H13 | J13: =I13 | K13: =J13 | L13: =K13
C14: 자연과학 | D14: 14 | F14: =기초자료_2024!D26 | G14: =기초자료_2025!D26 | H14: =G14 | I14: =H14 | J14: =I14 | K14: =J14 | L14: =K14
C15: 공학 | D15: 14 | F15: =기초자료_2024!E26 | G15: =기초자료_2025!E26 | H15: =G15 | I15: =H15 | J15: =I15 | K15: =J15 | L15: =K15
C16: 예체능 | D16: 14 | F16: =기초자료_2024!F26 | G16: =기초자료_2025!F26 | H16: =G16 | I16: =H16 | J16: =I16 | K16: =J16 | L16: =K16
A17: 본교(천안) 대학원 소계 | F17: =SUM(F13:F16) | G17: =SUM(G13:G16) | H17: =SUM(H13:H16) | I17: =SUM(I13:I16) | J17: =SUM(J13:J16) | K17: =SUM(K13:K16) | L17: =SUM(L13:L16)
A18: 서울캠퍼스 | B18: 대학원 | C18: 인문사회 | D18: 12 | F18: =기초자료_2024!C27 | G18: =기초자료_2025!C27 | H18: =G18 | I18: =H18 | J18: =I18 | K18: =J18 | L18: =K18
C19: 자연과학 | D19: 14 | F19: =기초자료_2024!D27 | G19: =기초자료_2025!D27 | H19: =G19 | I19: =H19 | J19: =I19 | K19: =J19 | L19: =K19
C20: 공학 | D20: 14 | F20: =기초자료_2024!E27 | G20: =기초자료_2025!E27 | H20: =G20 | I20: =H20 | J20: =I20 | K20: =J20 | L20: =K20
C21: 예체능 | D21: 14 | F21: =기초자료_2024!F27 | G21: =기초자료_2025!F27 | H21: =G21 | I21: =H21 | J21: =I21 | K21: =J21 | L21: =K21
A22: 서울캠퍼스 대학원 소계 | F22: =SUM(F18:F21) | G22: =SUM(G18:G21) | H22: =SUM(H18:H21) | I22: =SUM(I18:I21) | J22: =SUM(J18:J21) | K22: =SUM(K18:K21) | L22: =SUM(L18:L21)
A23: 합계 | F23: =F12+F17+F22 | G23: =G12+G17+G22 | H23: =H12+H17+H22 | I23: =I12+I17+I22 | J23: =J12+J17+J22 | K23: =K12+K17+K22 | L23: =L12+L17+L22
A25: STEP 2. 입학정원 시설정원 (명) — 정원 조정이 있을 때만 수정
A26: 학부: 계열별 입학정원 × 수업연한(4년) / 대학원: 주간 입학정원 × 수업연한. 모집유보 인원, 첨단학과 결손인원 활용분은 제외.
A27: 본교(천안) | B27: 학부 | C27: 인문사회 | D27: 12 | F27: =기초자료_2024!C21 | G27: =기초자료_2025!C21 | H27: =G27 | I27: =H27 | J27: =I27 | K27: =J27 | L27: =K27
C28: 자연과학 | D28: 14 | F28: =기초자료_2024!D21 | G28: =기초자료_2025!D21 | H28: =G28 | I28: =H28 | J28: =I28 | K28: =J28 | L28: =K28
C29: 공학 | D29: 14 | F29: =기초자료_2024!E21 | G29: =기초자료_2025!E21 | H29: =G29 | I29: =H29 | J29: =I29 | K29: =J29 | L29: =K29
C30: 예체능 | D30: 14 | F30: =기초자료_2024!F21 | G30: =기초자료_2025!F21 | H30: =G30 | I30: =H30 | J30: =I30 | K30: =J30 | L30: =K30
A31: 본교(천안) 학부 소계 | F31: =SUM(F27:F30) | G31: =SUM(G27:G30) | H31: =SUM(H27:H30) | I31: =SUM(I27:I30) | J31: =SUM(J27:J30) | K31: =SUM(K27:K30) | L31: =SUM(L27:L30)
A32: 본교(천안) | B32: 대학원 | C32: 인문사회 | D32: 12 | F32: =기초자료_2024!C22 | G32: =기초자료_2025!C22 | H32: =G32 | I32: =H32 | J32: =I32 | K32: =J32 | L32: =K32
C33: 자연과학 | D33: 14 | F33: =기초자료_2024!D22 | G33: =기초자료_2025!D22 | H33: =G33 | I33: =H33 | J33: =I33 | K33: =J33 | L33: =K33
C34: 공학 | D34: 14 | F34: =기초자료_2024!E22 | G34: =기초자료_2025!E22 | H34: =G34 | I34: =H34 | J34: =I34 | K34: =J34 | L34: =K34
C35: 예체능 | D35: 14 | F35: =기초자료_2024!F22 | G35: =기초자료_2025!F22 | H35: =G35 | I35: =H35 | J35: =I35 | K35: =J35 | L35: =K35
A36: 본교(천안) 대학원 소계 | F36: =SUM(F32:F35) | G36: =SUM(G32:G35) | H36: =SUM(H32:H35) | I36: =SUM(I32:I35) | J36: =SUM(J32:J35) | K36: =SUM(K32:K35) | L36: =SUM(L32:L35)
A37: 서울캠퍼스 | B37: 대학원 | C37: 인문사회 | D37: 12 | F37: =기초자료_2024!C23 | G37: =기초자료_2025!C23 | H37: =G37 | I37: =H37 | J37: =I37 | K37: =J37 | L37: =K37
C38: 자연과학 | D38: 14 | F38: =기초자료_2024!D23 | G38: =기초자료_2025!D23 | H38: =G38 | I38: =H38 | J38: =I38 | K38: =J38 | L38: =K38
C39: 공학 | D39: 14 | F39: =기초자료_2024!E23 | G39: =기초자료_2025!E23 | H39: =G39 | I39: =H39 | J39: =I39 | K39: =J39 | L39: =K39
C40: 예체능 | D40: 14 | F40: =기초자료_2024!F23 | G40: =기초자료_2025!F23 | H40: =G40 | I40: =H40 | J40: =I40 | K40: =J40 | L40: =K40
A41: 서울캠퍼스 대학원 소계 | F41: =SUM(F37:F40) | G41: =SUM(G37:G40) | H41: =SUM(H37:H40) | I41: =SUM(I37:I40) | J41: =SUM(J37:J40) | K41: =SUM(K37:K40) | L41: =SUM(L37:L40)
A42: 합계 | F42: =F31+F36+F41 | G42: =G31+G36+G41 | H42: =H31+H36+H41 | I42: =I31+I36+I41 | J42: =J31+J36+J41 | K42: =K31+K36+K41 | L42: =L31+L36+L41
A44: STEP 3. 교사 면적 증감 (㎡) — 신축·철거·용도변경이 있을 때만 입력 (늘면 +, 줄면 −)
...

Sheet 결과요약
A1: 결과요약 · 교사(校舍)시설 확보율 예측 (백석대학교 본교 = 천안 + 서울, 정보공시 기준)
A3: 조회 연도 ▶ | B3: 2027 | C3: ← 칸을 눌러 연도를 고르세요
A5: 재학생기준 확보율 | D5: 입학정원기준 확보율 | G5: 여유 면적(㎡) | J5: 판정
A6: =INDEX($F$17:$F$23,MATCH($B$3,$A$17:$A$23,0)) | D6: =INDEX($G$17:$G$23,MATCH($B$3,$A$17:$A$23,0)) | G6: =INDEX($J$17:$J$23,MATCH($B$3,$A$17:$A$23,0)) | J6: =INDEX($I$17:$I$23,MATCH($B$3,$A$17:$A$23,0))
A9: =$B$3&"년 재학생은 "&TEXT(INDEX($B$17:$B$23,MATCH($B$3,$A$17:$A$23,0)),"#,##0")&"명으로, 재학생기준 교사확보율은 "&TEXT(INDEX($F$17:$F$23,MATCH($B$3,$A$17:$A$23,0)),"0.0")&"%입니다. "&IF(INDEX($J$17:$J$23,MATCH($B$3,$A$17:$A$23,0))>=0,"법정 기준(100%)보다 "&TEXT(INDEX($J$17:$J$23,MATCH($B$3,$A$17:$A$23,0)),"#,##0")&"㎡ 여유가 있습니다.","법정 기준(100%)에 "&TEXT(-INDEX($J$17:$J$23,MATCH($B$3,$A$17:$A$23,0)),"#,##0")&"㎡ 부족합니다.")
A10: ="→ 이 상태에서 재학생이 100명 늘면 확보율이 약 "&TEXT(INDEX($F$17:$F$23,MATCH($B$3,$A$17:$A$23,0))-INDEX($E$17:$E$23,MATCH($B$3,$A$17:$A$23,0))/(INDEX($C$17:$C$23,MATCH($B$3,$A$17:$A$23,0))+1200)*100,"0.0")&"%p(인문사회) ~ "&TEXT(INDEX($F$17:$F$23,MATCH($B$3,$A$17:$A$23,0))-INDEX($E$17:$E$23,MATCH($B$3,$A$17:$A$23,0))/(INDEX($C$17:$C$23,MATCH($B$3,$A$17:$A$23,0))+1400)*100,"0.0")&"%p(자연·공학·예체능) 내려갑니다."
A11: ="→ 확보율 100%를 지키면서 더 받을 수 있는 재학생은 인문사회 기준 약 "&TEXT(INDEX($K$17:$K$23,MATCH($B$3,$A$17:$A$23,0)),"#,##0")&"명, 자연·공학·예체능 기준 약 "&TEXT(INDEX($L$17:$L$23,MATCH($B$3,$A$17:$A$23,0)),"#,##0")&"명입니다."
A15: 연도별 한눈에 보기
A16: 연도 | B16: 재학생 수 (명) | C16: 재학생 기준면적(B) | D16: 입학정원 기준면적(A) | E16: 교사 인정면적 (C+D+E) | F16: 재학생기준 확보율 | G16: 입학정원기준 확보율 | H16: 전년 대비 (재학생기준) | I16: 판정 | J16: 여유 면적 (인정면적−B) | K16: 추가로 받을 수 있는 재학생(인문사회) | L16: 추가로 받을 수 있는 재학생(자연·공·예체능) | N16: 기준선
A17: 2024 | B17: =입력!F23 | C17: =SUMPRODUCT(입력!$D$8:$D$11,입력!F8:F11)+SUMPRODUCT(입력!$D$13:$D$16,입력!F13:F16)+SUMPRODUCT(입력!$D$18:$D$21,입력!F18:F21) | D17: =SUMPRODUCT(입력!$D$27:$D$30,입력!F27:F30)+SUMPRODUCT(입력!$D$32:$D$35,입력!F32:F35)+SUMPRODUCT(입력!$D$37:$D$40,입력!F37:F40) | E17: =기초자료_2024!$E$16 | F17: =IF(C17=0,0,E17/C17*100) | G17: =IF(D17=0,0,E17/D17*100) | H17: - | I17: =IF(MIN(F17,G17)<100,"미달",IF(MIN(F17,G17)<사용안내!$C$27,"주의","적정")) | J17: =E17-C17 | K17: =IF(J17<0,0,ROUNDDOWN(J17/12,0)) | L17: =IF(J17<0,0,ROUNDDOWN(J17/14,0)) | N17: 100
A18: 2025 | B18: =입력!G23 | C18: =SUMPRODUCT(입력!$D$8:$D$11,입력!G8:G11)+SUMPRODUCT(입력!$D$13:$D$16,입력!G13:G16)+SUMPRODUCT(입력!$D$18:$D$21,입력!G18:G21) | D18: =SUMPRODUCT(입력!$D$27:$D$30,입력!G27:G30)+SUMPRODUCT(입력!$D$32:$D$35,입력!G32:G35)+SUMPRODUCT(입력!$D$37:$D$40,입력!G37:G40) | E18: =기초자료_2025!$E$16+SUM(입력!$G$46:G51) | F18: =IF(C18=0,0,E18/C18*100) | G18: =IF(D18=0,0,E18/D18*100) | H18: =F18-F17 | I18: =IF(MIN(F18,G18)<100,"미달",IF(MIN(F18,G18)<사용안내!$C$27,"주의","적정")) | J18: =E18-C18 | K18: =IF(J18<0,0,ROUNDDOWN(J18/12,0)) | L18: =IF(J18<0,0,ROUNDDOWN(J18/14,0)) | N18: 100
A19: 2026 | B19: =입력!H23 | C19: =SUMPRODUCT(입력!$D$8:$D$11,입력!H8:H11)+SUMPRODUCT(입력!$D$13:$D$16,입력!H13:H16)+SUMPRODUCT(입력!$D$18:$D$21,입력!H18:H21) | D19: =SUMPRODUCT(입력!$D$27:$D$30,입력!H27:H30)+SUMPRODUCT(입력!$D$32:$D$35,입력!H32:H35)+SUMPRODUCT(입력!$D$37:$D$40,입력!H37:H40) | E19: =기초자료_2025!$E$16+SUM(입력!$G$46:H51) | F19: =IF(C19=0,0,E19/C19*100) | G19: =IF(D19=0,0,E19/D19*100) | H19: =F19-F18 | I19: =IF(MIN(F19,G19)<100,"미달",IF(MIN(F19,G19)<사용안내!$C$27,"주의","적정")) | J19: =E19-C19 | K19: =IF(J19<0,0,ROUNDDOWN(J19/12,0)) | L19: =IF(J19<0,0,ROUNDDOWN(J19/14,0)) | N19: 100
A20: 2027 | B20: =입력!I23 | C20: =SUMPRODUCT(입력!$D$8:$D$11,입력!I8:I11)+SUMPRODUCT(입력!$D$13:$D$16,입력!I13:I16)+SUMPRODUCT(입력!$D$18:$D$21,입력!I18:I21) | D20: =SUMPRODUCT(입력!$D$27:$D$30,입력!I27:I30)+SUMPRODUCT(입력!$D$32:$D$35,입력!I32:I35)+SUMPRODUCT(입력!$D$37:$D$40,입력!I37:I40) | E20: =기초자료_2025!$E$16+SUM(입력!$G$46:I51) | F20: =IF(C20=0,0,E20/C20*100) | G20: =IF(D20=0,0,E20/D20*100) | H20: =F20-F19 | I20: =IF(MIN(F20,G20)<100,"미달",IF(MIN(F20,G20)<사용안내!$C$27,"주의","적정")) | J20: =E20-C20 | K20: =IF(J20<0,0,ROUNDDOWN(J20/12,0)) | L20: =IF(J20<0,0,ROUNDDOWN(J20/14,0)) | N20: 100
A21: 2028 | B21: =입력!J23 | C21: =SUMPRODUCT(입력!$D$8:$D$11,입력!J8:J11)+SUMPRODUCT(입력!$D$13:$D$16,입력!J13:J16)+SUMPRODUCT(입력!$D$18:$D$21,입력!J18:J21) | D21: =SUMPRODUCT(입력!$D$27:$D$30,입력!J27:J30)+SUMPRODUCT(입력!$D$32:$D$35,입력!J32:J35)+SUMPRODUCT(입력!$D$37:$D$40,입력!J37:J40) | E21: =기초자료_2025!$E$16+SUM(입력!$G$46:J51) | F21: =IF(C21=0,0,E21/C21*100) | G21: =IF(D21=0,0,E21/D21*100) | H21: =F21-F20 | I21: =IF(MIN(F21,G21)<100,"미달",IF(MIN(F21,G21)<사용안내!$C$27,"주의","적정")) | J21: =E21-C21 | K21: =IF(J21<0,0,ROUNDDOWN(J21/12,0)) | L21: =IF(J21<0,0,ROUNDDOWN(J21/14,0)) | N21: 100
A22: 2029 | B22: =입력!K23 | C22: =SUMPRODUCT(입력!$D$8:$D$11,입력!K8:K11)+SUMPRODUCT(입력!$D$13:$D$16,입력!K13:K16)+SUMPRODUCT(입력!$D$18:$D$21,입력!K18:K21) | D22: =SUMPRODUCT(입력!$D$27:$D$30,입력!K27:K30)+SUMPRODUCT(입력!$D$32:$D$35,입력!K32:K35)+SUMPRODUCT(입력!$D$37:$D$40,입력!K37:K40) | E22: =기초자료_2025!$E$16+SUM(입력!$G$46:K51) | F22: =IF(C22=0,0,E22/C22*100) | G22: =IF(D22=0,0,E22/D22*100) | H22: =F22-F21 | I22: =IF(MIN(F22,G22)<100,"미달",IF(MIN(F22,G22)<사용안내!$C$27,"주의","적정")) | J22: =E22-C22 | K22: =IF(J22<0,0,ROUNDDOWN(J22/12,0)) | L22: =IF(J22<0,0,ROUNDDOWN(J22/14,0)) | N22: 100
A23: 2030 | B23: =입력!L23 | C23: =SUMPRODUCT(입력!$D$8:$D$11,입력!L8:L11)+SUMPRODUCT(입력!$D$13:$D$16,입력!L13:L16)+SUMPRODUCT(입력!$D$18:$D$21,입력!L18:L21) | D23: =SUMPRODUCT(입력!$D$27:$D$30,입력!L27:L30)+SUMPRODUCT(입력!$D$32:$D$35,입력!L32:L35)+SUMPRODUCT(입력!$D$37:$D$40,입력!L37:L40) | E23: =기초자료_2025!$E$16+SUM(입력!$G$46:L51) | F23: =IF(C23=0,0,E23/C23*100) | G23: =IF(D23=0,0,E23/D23*100) | H23: =F23-F22 | I23: =IF(MIN(F23,G23)<100,"미달",IF(MIN(F23,G23)<사용안내!$C$27,"주의","적정")) | J23: =E23-C23 | K23: =IF(J23<0,0,ROUNDDOWN(J23/12,0)) | L23: =IF(J23<0,0,ROUNDDOWN(J23/14,0)) | N23: 100
A24: ※ 2024·2025는 실제 공시값과 같습니다(2024 재학생기준 134.7%·입학정원기준 142.4% / 2025 132%·141%). 판정: 100% 미만 = 미달, 100% 이상 ~ '주의 기준' 미만 = 주의(주의 기준은 사용안내 시트에서 변경)
A26: 정보공시 14-라 양식 미리보기 (단위: ㎡, %)
A27: 기준연도 | B27: 입학정원 기준 (A) | C27: 재학생 기준 (B) | D27: 기본시설 (C) | E27: 지원시설 (D) | F27: 연구시설 (E) | G27: 부속시설 | H27: 기타시설 | I27: 입학정원기준 (C+D+E)/A×100 | J27: 재학생기준 (C+D+E)/B×100
A28: 2024 | B28: =ROUND(D17,0) | C28: =ROUND(C17,0) | D28: =ROUND(기초자료_2024!$B$16,0) | E28: =ROUND(기초자료_2024!$C$16,0) | F28: =ROUND(기초자료_2024!$D$16,0) | G28: =ROUND(기초자료_2024!$F$6+기초자료_2024!$F$9,0) | H28: =ROUND(기초자료_2024!$G$6+기초자료_2024!$G$9,0) | I28: =ROUND(G17,1) | J28: =ROUND(F17,1)
A29: 2025 | B29: =ROUND(D18,0) | C29: =ROUND(C18,0) | D29: =ROUND(기초자료_2025!$B$16+SUM(입력!$G$46:G46)+SUM(입력!$G$49:G49),0) | E29: =ROUND(기초자료_2025!$C$16+SUM(입력!$G$47:G47)+SUM(입력!$G$50:G50),0) | F29: =ROUND(기초자료_2025!$D$16+SUM(입력!$G$48:G48)+SUM(입력!$G$51:G51),0) | G29: =ROUND(기초자료_2025!$F$6+기초자료_2025!$F$9,0) | H29: =ROUND(기초자료_2025!$G$6+기초자료_2025!$G$9,0) | I29: =ROUND(G18,1) | J29: =ROUND(F18,1)
A30: 2026 | B30: =ROUND(D19,0) | C30: =ROUND(C19,0) | D30: =ROUND(기초자료_2025!$B$16+SUM(입력!$G$46:H46)+SUM(입력!$G$49:H49),0) | E30: =ROUND(기초자료_2025!$C$16+SUM(입력!$G$47:H47)+SUM(입력!$G$50:H50),0) | F30: =ROUND(기초자료_2025!$D$16+SUM(입력!$G$48:H48)+SUM(입력!$G$51:H51),0) | G30: =ROUND(기초자료_2025!$F$6+기초자료_2025!$F$9,0) | H30: =ROUND(기초자료_2025!$G$6+기초자료_2025!$G$9,0) | I30: =ROUND(G19,1) | J30: =ROUND(F19,1)
A31: 2027 | B31: =ROUND(D20,0) | C31: =ROUND(C20,0) | D31: =ROUND(기초자료_2025!$B$16+SUM(입력!$G$46:I46)+SUM(입력!$G$49:I49),0) | E31: =ROUND(기초자료_2025!$C$16+SUM(입력!$G$47:I47)+SUM(입력!$G$50:I50),0) | F31: =ROUND(기초자료_2025!$D$16+SUM(입력!$G$48:I48)+SUM(입력!$G$51:I51),0) | G31: =ROUND(기초자료_2025!$F$6+기초자료_2025!$F$9,0) | H31: =ROUND(기초자료_2025!$G$6+기초자료_2025!$G$9,0) | I31: =ROUND(G20,1) | J31: =ROUND(F20,1)
A32: 2028 | B32: =ROUND(D21,0) | C32: =ROUND(C21,0) | D32: =ROUND(기초자료_2025!$B$16+SUM(입력!$G$46:J46)+SUM(입력!$G$49:J49),0) | E32: =ROUND(기초자료_2025!$C$16+SUM(입력!$G$47:J47)+SUM(입력!$G$50:J50),0) | F32: =ROUND(기초자료_2025!$D$16+SUM(입력!$G$48:J48)+SUM(입력!$G$51:J51),0) | G32: =ROUND(기초자료_2025!$F$6+기초자료_2025!$F$9,0) | H32: =ROUND(기초자료_2025!$G$6+기초자료_2025!$G$9,0) | I32: =ROUND(G21,1) | J32: =ROUND(F21,1)
A33: 2029 | B33: =ROUND(D22,0) | C33: =ROUND(C22,0) | D33: =ROUND(기초자료_2025!$B$16+SUM(입력!$G$46:K46)+SUM(입력!$G$49:K49),0) | E33: =ROUND(기초자료_2025!$C$16+SUM(입력!$G$47:K47)+SUM(입력!$G$50:K50),0) | F33: =ROUND(기초자료_2025!$D$16+SUM(입력!$G$48:K48)+SUM(입력!$G$51:K51),0) | G33: =ROUND(기초자료_2025!$F$6+기초자료_2025!$F$9,0) | H33: =ROUND(기초자료_2025!$G$6+기초자료_2025!$G$9,0) | I33: =ROUND(G22,1) | J33: =ROUND(F22,1)
A34: 2030 | B34: =ROUND(D23,0) | C34: =ROUND(C23,0) | D34: =ROUND(기초자료_2025!$B$16+SUM(입력!$G$46:L46)+SUM(입력!$G$49:L49),0) | E34: =ROUND(기초자료_2025!$C$16+SUM(입력!$G$47:L47)+SUM(입력!$G$50:L50),0) | F34: =ROUND(기초자료_2025!$D$16+SUM(입력!$G$48:L48)+SUM(입력!$G$51:L51),0) | G34: =ROUND(기초자료_2025!$F$6+기초자료_2025!$F$9,0) | H34: =ROUND(기초자료_2025!$G$6+기초자료_2025!$G$9,0) | I34: =ROUND(G23,1) | J34: =ROUND(F23,1)
A35: ※ 확보율은 소수 첫째자리로 표시(2024 공시는 소수 첫째자리, 2025 공시는 정수 표기). 부속·기타시설은 확보율과 무관해 2025 이후는 2025 값을 표시. 2024·2025행은 실제 공시값과 일치합니다.
A37: 캠퍼스별 확보율 (집계표 1-1과 같은 방식)
A38: 연도 | B38: 천안 재학생기준 | C38: 천안 입학정원기준 | D38: 서울 재학생기준 | E38: 서울 입학정원기준 | F38: 천안 인정면적 | G38: 서울 인정면적
A39: 2024 | B39: =F39/(SUMPRODUCT(입력!$D$8:$D$11,입력!F8:F11)+SUMPRODUCT(입력!$D$13:$D$16,입력!F13:F16))*100 | C39: =F39/(SUMPRODUCT(입력!$D$27:$D$30,입력!F27:F30)+SUMPRODUCT(입력!$D$32:$D$35,입력!F32:F35))*100 | D39: =G39/(SUMPRODUCT(입력!$D$18:$D$21,입력!F18:F21))*100 | E39: =G39/(SUMPRODUCT(입력!$D$37:$D$40,입력!F37:F40))*100 | F39: =기초자료_2024!$E$14 | G39: =기초자료_2024!$E$15
A40: 2025 | B40: =F40/(SUMPRODUCT(입력!$D$8:$D$11,입력!G8:G11)+SUMPRODUCT(입력!$D$13:$D$16,입력!G13:G16))*100 | C40: =F40/(SUMPRODUCT(입력!$D$27:$D$30,입력!G27:G30)+SUMPRODUCT(입력!$D$32:$D$35,입력!G32:G35))*100 | D40: =G40/(SUMPRODUCT(입력!$D$18:$D$21,입력!G18:G21))*100 | E40: =G40/(SUMPRODUCT(입력!$D$37:$D$40,입력!G37:G40))*100 | F40: =기초자료_2025!$E$14+SUM(입력!$G$46:G48) | G40: =기초자료_2025!$E$15+SUM(입력!$G$49:G51)
A41: 2026 | B41: =F41/(SUMPRODUCT(입력!$D$8:$D$11,입력!H8:H11)+SUMPRODUCT(입력!$D$13:$D$16,입력!H13:H16))*100 | C41: =F41/(SUMPRODUCT(입력!$D$27:$D$30,입력!H27:H30)+SUMPRODUCT(입력!$D$32:$D$35,입력!H32:H35))*100 | D41: =G41/(SUMPRODUCT(입력!$D$18:$D$21,입력!H18:H21))*100 | E41: =G41/(SUMPRODUCT(입력!$D$37:$D$40,입력!H37:H40))*100 | F41: =기초자료_2025!$E$14+SUM(입력!$G$46:H48) | G41: =기초자료_2025!$E$15+SUM(입력!$G$49:H51)
A42: 2027 | B42: =F42/(SUMPRODUCT(입력!$D$8:$D$11,입력!I8:I11)+SUMPRODUCT(입력!$D$13:$D$16,입력!I13:I16))*100 | C42: =F42/(SUMPRODUCT(입력!$D$27:$D$30,입력!I27:I30)+SUMPRODUCT(입력!$D$32:$D$35,입력!I32:I35))*100 | D42: =G42/(SUMPRODUCT(입력!$D$18:$D$21,입력!I18:I21))*100 | E42: =G42/(SUMPRODUCT(입력!$D$37:$D$40,입력!I37:I40))*100 | F42: =기초자료_2025!$E$14+SUM(입력!$G$46:I48) | G42: =기초자료_2025!$E$15+SUM(입력!$G$49:I51)
A43: 2028 | B43: =F43/(SUMPRODUCT(입력!$D$8:$D$11,입력!J8:J11)+SUMPRODUCT(입력!$D$13:$D$16,입력!J13:J16))*100 | C43: =F43/(SUMPRODUCT(입력!$D$27:$D$30,입력!J27:J30)+SUMPRODUCT(입력!$D$32:$D$35,입력!J32:J35))*100 | D43: =G43/(SUMPRODUCT(입력!$D$18:$D$21,입력!J18:J21))*100 | E43: =G43/(SUMPRODUCT(입력!$D$37:$D$40,입력!J37:J40))*100 | F43: =기초자료_2025!$E$14+SUM(입력!$G$46:J48) | G43: =기초자료_2025!$E$15+SUM(입력!$G$49:J51)
A44: 2029 | B44: =F44/(SUMPRODUCT(입력!$D$8:$D$11,입력!K8:K11)+SUMPRODUCT(입력!$D$13:$D$16,입력!K13:K16))*100 | C44: =F44/(SUMPRODUCT(입력!$D$27:$D$30,입력!K27:K30)+SUMPRODUCT(입력!$D$32:$D$35,입력!K32:K35))*100 | D44: =G44/(SUMPRODUCT(입력!$D$18:$D$21,입력!K18:K21))*100 | E44: =G44/(SUMPRODUCT(입력!$D$37:$D$40,입력!K37:K40))*100 | F44: =기초자료_2025!$E$14+SUM(입력!$G$46:K48) | G44: =기초자료_2025!$E$15+SUM(입력!$G$49:K51)
A45: 2030 | B45: =F45/(SUMPRODUCT(입력!$D$8:$D$11,입력!L8:L11)+SUMPRODUCT(입력!$D$13:$D$16,입력!L13:L16))*100 | C45: =F45/(SUMPRODUCT(입력!$D$27:$D$30,입력!L27:L30)+SUMPRODUCT(입력!$D$32:$D$35,입력!L32:L35))*100 | D45: =G45/(SUMPRODUCT(입력!$D$18:$D$21,입력!L18:L21))*100 | E45: =G45/(SUMPRODUCT(입력!$D$37:$D$40,입력!L37:L40))*100 | F45: =기초자료_2025!$E$14+SUM(입력!$G$46:L48) | G45: =기초자료_2025!$E$15+SUM(입력!$G$49:L51)
A48: 2024 → 2025 실적 변화 요인 — 확보율이 왜 바뀌었나?
A49: 계열 | B49: 1인당 기준면적 | C49: 2024 재학생 | D49: 2025 재학생 | E49: 재학생 증감 | F49: 기준면적 변화(㎡) | G49: 확보율 영향(%p) | I49: ="▶ 2024 → 2025: 재학생 "&TEXT(E54,"+#,##0;-#,##0;0")&"명, 재학생 기준면적 "&TEXT(F54,"+#,##0;-#,##0;0")&"㎡, 교사 인정면적 "&IF(E55=0,"변동 없음",TEXT(E55,"+#,##0;-#,##0")&"㎡")&" → 재학생기준 확보율 "&TEXT(F17,"0.0")&"% → "&TEXT(F18,"0.0")&"% ("&TEXT(G54,"+0.0;-0.0;0.0")&"%p). 입학정원기준은 "&TEXT(G17,"0.0")&"% → "&TEXT(G18,"0.0")&"%."
A50: 인문사회 | B50: 12 | C50: =입력!F8+입력!F13+입력!F18 | D50: =입력!G8+입력!G13+입력!G18 | E50: =D50-C50 | F50: =E50*B50 | G50: =IF(F50=0,0,$E$18/($C$17+F50)*100-$F$17)
A51: 자연과학 | B51: 14 | C51: =입력!F9+입력!F14+입력!F19 | D51: =입력!G9+입력!G14+입력!G19 | E51: =D51-C51 | F51: =E51*B51 | G51: =IF(F51=0,0,$E$18/($C$17+F51)*100-$F$17)
...

Sheet 민감도
A1: 민감도 분석 · 재학생이 늘거나 줄면 교사확보율은 어떻게 될까?
A2: 이 시트로 알 수 있는 것 ①재학생 증감에 따른 확보율 변화 ②확보율 목표를 지키려면 재학생을 최대 몇 명까지 늘릴 수 있는지 ③계열을 섞어 늘릴 때의 결과. 노란 칸만 바꾸면 됩니다.
A4: 0단계 · 기준 정하기 — 어느 해 상태에서 출발할지 고릅니다
A5: 기준 연도 | B5: 2025 | D5: 기준 재학생 수(명) | E5: =INDEX(결과요약!$B$17:$B$23,MATCH($B$5,결과요약!$A$17:$A$23,0)) | H5: 현재 재학생기준 확보율 | J5: =IF(E6=0,0,E7/E6*100)
A6: 표 증감 간격(명) | B6: 250 | D6: 재학생 기준면적 B(㎡) | E6: =INDEX(결과요약!$C$17:$C$23,MATCH($B$5,결과요약!$A$17:$A$23,0)) | H6: 여유 면적(㎡) | J6: =E7-E6
A7: ↑ 연도는 결과요약 시트의 예측값을 그대로 가져옵니다. | D7: 교사 인정면적(㎡) | E7: =INDEX(결과요약!$E$17:$E$23,MATCH($B$5,결과요약!$A$17:$A$23,0)) | H7: 입학정원 시설정원(명) | J7: =INDEX(입력!$F$42:$K$42,MATCH($B$5,결과요약!$A$17:$A$23,0))
A9: 1단계 · 한눈에 보는 핵심 (숫자가 바뀌면 문장도 자동으로 바뀝니다)
A10: ="● 현재("&$B$5&"년) 재학생은 "&TEXT(E5,"#,##0")&"명, 재학생기준 확보율은 "&TEXT(J5,"0.0")&"%이며, 법정 기준(100%)보다 "&TEXT(J6,"#,##0")&"㎡ 여유가 있습니다."
A11: ="● 재학생 1명이 늘면 기준면적이 인문사회는 12㎡, 자연과학·공학·예체능은 14㎡ 늘어납니다. 100명 늘면 확보율이 약 "&TEXT(J5-E7/(E6+1200)*100,"0.0")&"%p(인문사회) ~ "&TEXT(J5-E7/(E6+1400)*100,"0.0")&"%p(자연·공학·예체능) 내려갑니다."
A12: =IF(J6<0,"● 이미 법정 기준(100%)에 미달합니다.","● 확보율이 100% 아래로 떨어지려면 재학생이 인문사회만 늘 경우 "&TEXT(ROUNDDOWN(J6/12,0)+1,"#,##0")&"명 이상, 자연·공학·예체능만 늘 경우 "&TEXT(ROUNDDOWN(J6/14,0)+1,"#,##0")&"명 이상 늘어야 합니다.")
A13: =IF(J5<사용안내!$C$27,"● 이미 주의 기준("&사용안내!$C$27&"%)보다 낮습니다.","● 주의 기준("&사용안내!$C$27&"%)까지는 인문사회 "&TEXT(ROUNDDOWN((E7/사용안내!$C$27*100-E6)/12,0),"#,##0")&"명, 자연·공학·예체능 "&TEXT(ROUNDDOWN((E7/사용안내!$C$27*100-E6)/14,0),"#,##0")&"명까지 늘어도 됩니다.")
A14: =IF(E5>J7,"● 재학생이 "&TEXT(E5-J7,"#,##0")&"명 넘게 줄면 재학생 수가 입학정원 시설정원("&TEXT(J7,"#,##0")&"명)보다 적어집니다. 이때부터는 재학생 기준면적 이상만 보유하면 법정 기준을 충족합니다(지침 ※ 조항).","● 재학생 수가 이미 입학정원 시설정원보다 적어, 재학생 기준면적이 법정 의무 기준입니다.")
A16: 2단계 · 계산 원리 — 예시 숫자로 따라가 보기
A17: 공식: 재학생기준 확보율 = 교사 인정면적 ÷ ( 현재 재학생 기준면적 + 늘어난 재학생 × 1인당 기준면적 ) × 100
A18: 1인당 기준면적은 인문사회 12㎡, 자연과학·공학·예체능 14㎡ (운영 중인 대학, 학부·대학원 구분 없음). 줄어드는 경우는 음수(−)로 넣으면 됩니다.
A19: 예시 증감 인원(명) | C19: 500 | D19: 계열 선택 | E19: 인문사회 | G19: 1인당 기준면적 | H19: =IF(E19="인문사회",12,14)
A20: 순서 | B20: 내용 | D20: 계산식 | J20: 결과
A21: ① | B21: 늘어나는 기준면적 | D21: =TEXT(C19,"#,##0")&"명 × "&H19&"㎡" | J21: =C19*H19
A22: ② | B22: 새 재학생 기준면적 | D22: =TEXT(E6,"#,##0")&" + "&TEXT(C19*H19,"#,##0") | J22: =E6+C19*H19
A23: ③ | B23: 새 확보율 | D23: =TEXT(E7,"#,##0")&" ÷ "&TEXT(E6+C19*H19,"#,##0")&" × 100" | J23: =IF(E6+C19*H19<=0,0,E7/(E6+C19*H19)*100)
A24: ④ | B24: 현재 대비 변화 | D24: =TEXT(J5,"0.0")&"% → "&TEXT(J23,"0.0")&"%" | J24: =J23-J5
A27: 3단계 · 재학생 증감별 확보율 표 — 한 계열만 늘거나 줄었다고 가정
A28: 읽는 법: 왼쪽 '재학생 증감'만큼 해당 계열 재학생이 바뀌면 오른쪽 확보율이 됩니다. 파란 줄이 현재. 빨강=100% 미만(미달), 노랑=주의 기준 미만, 초록=적정.
C29: 인문사회 계열이 바뀔 때 (1인당 12㎡) | G29: 자연과학·공학·예체능이 바뀔 때 (1인당 14㎡)
A30: 재학생 증감 (명) | B30: 전체 재학생 (명) | C30: 재학생 기준면적(㎡) | D30: 확보율 | E30: 현재 대비 | F30: 판정 | G30: 재학생 기준면적(㎡) | H30: 확보율 | I30: 현재 대비 | J30: 판정
A31: =$B$6*-6 | B31: =$E$5+A31 | C31: =$E$6+A31*12 | D31: =IF(C31<=0,0,$E$7/C31*100) | E31: =D31-$J$5 | F31: =IF(D31<100,"미달",IF(D31<사용안내!$C$27,"주의","적정")) | G31: =$E$6+A31*14 | H31: =IF(G31<=0,0,$E$7/G31*100) | I31: =H31-$J$5 | J31: =IF(H31<100,"미달",IF(H31<사용안내!$C$27,"주의","적정"))
A32: =$B$6*-5 | B32: =$E$5+A32 | C32: =$E$6+A32*12 | D32: =IF(C32<=0,0,$E$7/C32*100) | E32: =D32-$J$5 | F32: =IF(D32<100,"미달",IF(D32<사용안내!$C$27,"주의","적정")) | G32: =$E$6+A32*14 | H32: =IF(G32<=0,0,$E$7/G32*100) | I32: =H32-$J$5 | J32: =IF(H32<100,"미달",IF(H32<사용안내!$C$27,"주의","적정"))
A33: =$B$6*-4 | B33: =$E$5+A33 | C33: =$E$6+A33*12 | D33: =IF(C33<=0,0,$E$7/C33*100) | E33: =D33-$J$5 | F33: =IF(D33<100,"미달",IF(D33<사용안내!$C$27,"주의","적정")) | G33: =$E$6+A33*14 | H33: =IF(G33<=0,0,$E$7/G33*100) | I33: =H33-$J$5 | J33: =IF(H33<100,"미달",IF(H33<사용안내!$C$27,"주의","적정"))
A34: =$B$6*-3 | B34: =$E$5+A34 | C34: =$E$6+A34*12 | D34: =IF(C34<=0,0,$E$7/C34*100) | E34: =D34-$J$5 | F34: =IF(D34<100,"미달",IF(D34<사용안내!$C$27,"주의","적정")) | G34: =$E$6+A34*14 | H34: =IF(G34<=0,0,$E$7/G34*100) | I34: =H34-$J$5 | J34: =IF(H34<100,"미달",IF(H34<사용안내!$C$27,"주의","적정"))
A35: =$B$6*-2 | B35: =$E$5+A35 | C35: =$E$6+A35*12 | D35: =IF(C35<=0,0,$E$7/C35*100) | E35: =D35-$J$5 | F35: =IF(D35<100,"미달",IF(D35<사용안내!$C$27,"주의","적정")) | G35: =$E$6+A35*14 | H35: =IF(G35<=0,0,$E$7/G35*100) | I35: =H35-$J$5 | J35: =IF(H35<100,"미달",IF(H35<사용안내!$C$27,"주의","적정"))
A36: =$B$6*-1 | B36: =$E$5+A36 | C36: =$E$6+A36*12 | D36: =IF(C36<=0,0,$E$7/C36*100) | E36: =D36-$J$5 | F36: =IF(D36<100,"미달",IF(D36<사용안내!$C$27,"주의","적정")) | G36: =$E$6+A36*14 | H36: =IF(G36<=0,0,$E$7/G36*100) | I36: =H36-$J$5 | J36: =IF(H36<100,"미달",IF(H36<사용안내!$C$27,"주의","적정"))
A37: =$B$6*0 | B37: =$E$5+A37 | C37: =$E$6+A37*12 | D37: =IF(C37<=0,0,$E$7/C37*100) | E37: =D37-$J$5 | F37: =IF(D37<100,"미달",IF(D37<사용안내!$C$27,"주의","적정")) | G37: =$E$6+A37*14 | H37: =IF(G37<=0,0,$E$7/G37*100) | I37: =H37-$J$5 | J37: =IF(H37<100,"미달",IF(H37<사용안내!$C$27,"주의","적정"))
A38: =$B$6*1 | B38: =$E$5+A38 | C38: =$E$6+A38*12 | D38: =IF(C38<=0,0,$E$7/C38*100) | E38: =D38-$J$5 | F38: =IF(D38<100,"미달",IF(D38<사용안내!$C$27,"주의","적정")) | G38: =$E$6+A38*14 | H38: =IF(G38<=0,0,$E$7/G38*100) | I38: =H38-$J$5 | J38: =IF(H38<100,"미달",IF(H38<사용안내!$C$27,"주의","적정"))
A39: =$B$6*2 | B39: =$E$5+A39 | C39: =$E$6+A39*12 | D39: =IF(C39<=0,0,$E$7/C39*100) | E39: =D39-$J$5 | F39: =IF(D39<100,"미달",IF(D39<사용안내!$C$27,"주의","적정")) | G39: =$E$6+A39*14 | H39: =IF(G39<=0,0,$E$7/G39*100) | I39: =H39-$J$5 | J39: =IF(H39<100,"미달",IF(H39<사용안내!$C$27,"주의","적정"))
A40: =$B$6*3 | B40: =$E$5+A40 | C40: =$E$6+A40*12 | D40: =IF(C40<=0,0,$E$7/C40*100) | E40: =D40-$J$5 | F40: =IF(D40<100,"미달",IF(D40<사용안내!$C$27,"주의","적정")) | G40: =$E$6+A40*14 | H40: =IF(G40<=0,0,$E$7/G40*100) | I40: =H40-$J$5 | J40: =IF(H40<100,"미달",IF(H40<사용안내!$C$27,"주의","적정"))
A41: =$B$6*4 | B41: =$E$5+A41 | C41: =$E$6+A41*12 | D41: =IF(C41<=0,0,$E$7/C41*100) | E41: =D41-$J$5 | F41: =IF(D41<100,"미달",IF(D41<사용안내!$C$27,"주의","적정")) | G41: =$E$6+A41*14 | H41: =IF(G41<=0,0,$E$7/G41*100) | I41: =H41-$J$5 | J41: =IF(H41<100,"미달",IF(H41<사용안내!$C$27,"주의","적정"))
A42: =$B$6*5 | B42: =$E$5+A42 | C42: =$E$6+A42*12 | D42: =IF(C42<=0,0,$E$7/C42*100) | E42: =D42-$J$5 | F42: =IF(D42<100,"미달",IF(D42<사용안내!$C$27,"주의","적정")) | G42: =$E$6+A42*14 | H42: =IF(G42<=0,0,$E$7/G42*100) | I42: =H42-$J$5 | J42: =IF(H42<100,"미달",IF(H42<사용안내!$C$27,"주의","적정"))
A43: =$B$6*6 | B43: =$E$5+A43 | C43: =$E$6+A43*12 | D43: =IF(C43<=0,0,$E$7/C43*100) | E43: =D43-$J$5 | F43: =IF(D43<100,"미달",IF(D43<사용안내!$C$27,"주의","적정")) | G43: =$E$6+A43*14 | H43: =IF(G43<=0,0,$E$7/G43*100) | I43: =H43-$J$5 | J43: =IF(H43<100,"미달",IF(H43<사용안내!$C$27,"주의","적정"))
A46: 4단계 · 거꾸로 계산하기 — 목표 확보율을 지키려면 재학생을 최대 몇 명까지 늘릴 수 있나?
A47: 목표 확보율(노란 칸)은 바꿀 수 있습니다. 결과가 음수(−)이면 그 목표를 맞추려면 오히려 그만큼 재학생이 줄어야(또는 면적이 늘어야) 한다는 뜻입니다.
...

Sheet 기초자료_2025
A1: 기초자료 · 2025 시설현황 집계표 / 2025 정보공시(14-라)
A2: 이 시트는 원자료 보관용입니다. 수정할 필요가 없습니다. (파란 글씨 = 집계표에서 옮겨 적은 값)
A4: 1. 건물 보유면적 (집계표 1-3, ㎡)
A5: 캠퍼스 | B5: 위치 | C5: 교육기본시설 | D5: 지원시설 | E5: 연구시설 | F5: 부속시설 | G5: 기타시설 | H5: 임대시설 | I5: 교사보유면적 (집계표)
A6: 본교(천안) | B6: 교지경계선 내 | C6: 146250.18 | D6: 49778.99 | E6: 0 | F6: 4252.54 | G6: 497 | H6: 5178.83 | I6: 201208
A7: 본교(천안) | B7: 20km 이내 | C7: 6569.73 | D7: 0 | E7: 0 | F7: 2374.25 | G7: 7778.51 | H7: 0 | I7: 0
A8: 본교(천안) | B8: 20km 외 | C8: 0 | D8: 0 | E8: 2942.06 | F8: 0 | G8: 0 | H8: 0 | I8: 0
A9: 서울캠퍼스 | B9: 교지경계선 내 | C9: 18570.5 | D9: 945.96 | E9: 0 | F9: 0 | G9: 0 | H9: 0 | I9: 19516.46
A10: 서울캠퍼스 | B10: 20km 이내 | C10: 0 | D10: 4794.83 | E10: 0 | F10: 0 | G10: 0 | H10: 0 | I10: 4794.83
A12: 2. 확보율 계산에 들어가는 면적 (C 기본 · D 지원 · E 연구)
A13: 캠퍼스 | B13: 기본시설(C) | C13: 지원시설(D) | D13: 연구시설(E) | E13: 계 | F13: 집계표 교사보유면적 | G13: 차이 | H13: 어떻게 계산했나
A14: 본교(천안) | B14: =C6+H6 | C14: =D6 | D14: =E6 | E14: =SUM(B14:D14) | F14: =I6+I7+I8 | G14: =E14-F14 | H14: 교지경계선 내 기본+지원+연구 + 임대시설(학생후생복지) 5,178.83㎡. 20km 이내 기본 6,569.73㎡ · 20km 외 연구 2,942.06㎡은 미인정
A15: 서울캠퍼스 | B15: =C9 | C15: =D9+D10 | D15: =E9 | E15: =SUM(B15:D15) | F15: =I9+I10 | G15: =E15-F15 | H15: 교지경계선 내 기본+지원 + 20km 이내 학생기숙사(조이하우스) 4,794.83㎡
A16: 합계 | B16: =SUM(B14:B15) | C16: =SUM(C14:C15) | D16: =SUM(D14:D15) | E16: =SUM(E14:E15) | F16: =SUM(F14:F15) | G16: =SUM(G14:G15)
A18: 3. 시설정원 (집계표 2-2, 명)
A19: 캠퍼스 | B19: 과정 | C19: 인문사회 | D19: 자연과학 | E19: 공학 | F19: 예체능 | G19: 계
A20: 입학정원 기준 (수업연한 곱한 값)
A21: 본교(천안) | B21: 학부 | C21: 4032 | D21: 4488 | E21: 0 | F21: 2640 | G21: =SUM(C21:F21)
A22: 본교(천안) | B22: 대학원 | C22: 55 | D22: 25 | E22: 6 | F22: 0 | G22: =SUM(C22:F22)
A23: 서울캠퍼스 | B23: 대학원 | C23: 886 | D23: 0 | E23: 0 | F23: 0 | G23: =SUM(C23:F23)
A24: 재학생 기준 (2025.4.1.)
A25: 본교(천안) | B25: 학부 | C25: 4792 | D25: 4045 | E25: 0 | F25: 2737 | G25: =SUM(C25:F25)
A26: 본교(천안) | B26: 대학원 | C26: 228 | D26: 30 | E26: 229 | F26: 0 | G26: =SUM(C26:F26)
A27: 서울캠퍼스 | B27: 대학원 | C27: 1001 | D27: 0 | E27: 0 | F27: 0 | G27: =SUM(C27:F27)
A29: 4. 본교(천안) 학부 학년별 재학생 (집계표 2-3, 주간 · 야간 0명)
A30: 계열 | B30: 1학년 | C30: 2학년 | D30: 3학년 | E30: 4학년 | F30: 계 | G30: 3번 표와 차이
A31: 인문사회 | B31: 1154 | C31: 1068 | D31: 1228 | E31: 1342 | F31: =SUM(B31:E31) | G31: =F31-C25
A32: 자연과학 | B32: 1304 | C32: 901 | D32: 972 | E32: 868 | F32: =SUM(B32:E32) | G32: =F32-D25
A33: 공학 | B33: 0 | C33: 0 | D33: 0 | E33: 0 | F33: =SUM(B33:E33) | G33: =F33-E25
A34: 예체능 | B34: 694 | C34: 615 | D34: 684 | E34: 744 | F34: =SUM(B34:E34) | G34: =F34-F25
A36: 5. 2025 정보공시(14-라) 값과 이 시트로 계산한 값 대조
A37: 항목 | B37: 공시값 | C37: 계산값(원값) | D37: 계산값(공시 표기) | E37: 차이
A38: 입학정원 기준면적(A) | B38: 159902 | C38: =SUM(C21:C23)*12+SUM(D21:F23)*14 | D38: =ROUND(C38,0) | E38: =D38-B38
A39: 재학생 기준면적(B) | B39: 170826 | C39: =SUM(C25:C27)*12+SUM(D25:F27)*14 | D39: =ROUND(C39,0) | E39: =D39-B39
A40: 기본시설(C) | B40: 170000 | C40: =B16 | D40: =ROUND(C40,0) | E40: =D40-B40
A41: 지원시설(D) | B41: 55520 | C41: =C16 | D41: =ROUND(C41,0) | E41: =D41-B41
A42: 연구시설(E) | B42: 0 | C42: =D16 | D42: =ROUND(C42,0) | E42: =D42-B42
A43: 부속시설(교지경계선 내) | B43: 4253 | C43: =F6+F9 | D43: =ROUND(C43,0) | E43: =D43-B43
A44: 기타시설(교지경계선 내) | B44: 497 | C44: =G6+G9 | D44: =ROUND(C44,0) | E44: =D44-B44
A45: 입학정원기준 확보율(%) | B45: 141 | C45: =E16/C38*100 | D45: =ROUND(C45,0) | E45: =D45-B45
...

Sheet 기초자료_2024
A1: 기초자료 · 2024 시설현황 집계표 / 2024 정보공시(14-라)
A2: 이 시트는 원자료 보관용입니다. 수정할 필요가 없습니다. (파란 글씨 = 집계표에서 옮겨 적은 값)
A4: 1. 건물 보유면적 (집계표 1-3, ㎡)
A5: 캠퍼스 | B5: 위치 | C5: 교육기본시설 | D5: 지원시설 | E5: 연구시설 | F5: 부속시설 | G5: 기타시설 | H5: 임대시설 | I5: 교사보유면적 (집계표)
A6: 본교(천안) | B6: 교지경계선 내 | C6: 146250.18 | D6: 49778.99 | E6: 0 | F6: 4252.54 | G6: 497 | H6: 5178.83 | I6: 201208
A7: 본교(천안) | B7: 20km 이내 | C7: 6569.73 | D7: 0 | E7: 0 | F7: 3509.25 | G7: 16254.57 | H7: 5904.37 | I7: 0
A8: 본교(천안) | B8: 20km 외 | C8: 0 | D8: 0 | E8: 2942.06 | F8: 0 | G8: 0 | H8: 0 | I8: 0
A9: 서울캠퍼스 | B9: 교지경계선 내 | C9: 18570.5 | D9: 945.96 | E9: 0 | F9: 0 | G9: 0 | H9: 0 | I9: 19516.46
A10: 서울캠퍼스 | B10: 20km 이내 | C10: 0 | D10: 4794.83 | E10: 0 | F10: 0 | G10: 0 | H10: 0 | I10: 4794.83
A12: 2. 확보율 계산에 들어가는 면적 (C 기본 · D 지원 · E 연구)
A13: 캠퍼스 | B13: 기본시설(C) | C13: 지원시설(D) | D13: 연구시설(E) | E13: 계 | F13: 집계표 교사보유면적 | G13: 차이 | H13: 어떻게 계산했나
A14: 본교(천안) | B14: =C6+H6 | C14: =D6 | D14: =E6 | E14: =SUM(B14:D14) | F14: =I6+I7+I8 | G14: =E14-F14 | H14: 교지경계선 내 기본+지원+연구 + 임대시설(학생후생복지) 5,178.83㎡. 20km 이내 기본 6,569.73㎡ · 일반임대 5,904.37㎡ · 20km 외 연구 2,942.06㎡은 미인정
A15: 서울캠퍼스 | B15: =C9 | C15: =D9+D10 | D15: =E9 | E15: =SUM(B15:D15) | F15: =I9+I10 | G15: =E15-F15 | H15: 교지경계선 내 기본+지원 + 20km 이내 학생기숙사(조이하우스) 4,794.83㎡
A16: 합계 | B16: =SUM(B14:B15) | C16: =SUM(C14:C15) | D16: =SUM(D14:D15) | E16: =SUM(E14:E15) | F16: =SUM(F14:F15) | G16: =SUM(G14:G15)
A18: 3. 시설정원 (집계표 2-2, 명)
A19: 캠퍼스 | B19: 과정 | C19: 인문사회 | D19: 자연과학 | E19: 공학 | F19: 예체능 | G19: 계
A20: 입학정원 기준 (수업연한 곱한 값)
A21: 본교(천안) | B21: 학부 | C21: 4648 | D21: 3852 | E21: 0 | F21: 2660 | G21: =SUM(C21:F21)
A22: 본교(천안) | B22: 대학원 | C22: 0 | D22: 25 | E22: 20 | F22: 0 | G22: =SUM(C22:F22)
A23: 서울캠퍼스 | B23: 대학원 | C23: 900 | D23: 0 | E23: 0 | F23: 0 | G23: =SUM(C23:F23)
A24: 재학생 기준 (2024.4.1.)
A25: 본교(천안) | B25: 학부 | C25: 5106 | D25: 3707 | E25: 0 | F25: 2773 | G25: =SUM(C25:F25)
A26: 본교(천안) | B26: 대학원 | C26: 125 | D26: 20 | E26: 126 | F26: 0 | G26: =SUM(C26:F26)
A27: 서울캠퍼스 | B27: 대학원 | C27: 995 | D27: 0 | E27: 0 | F27: 0 | G27: =SUM(C27:F27)
A29: 4. 본교(천안) 학부 학년별 재학생 (집계표 2-3, 주간 · 야간 0명)
A30: 계열 | B30: 1학년 | C30: 2학년 | D30: 3학년 | E30: 4학년 | F30: 계 | G30: 3번 표와 차이
A31: 인문사회 | B31: 1274 | C31: 1188 | D31: 1221 | E31: 1423 | F31: =SUM(B31:E31) | G31: =F31-C25
A32: 자연과학 | B32: 1091 | C32: 910 | D32: 808 | E32: 898 | F32: =SUM(B32:E32) | G32: =F32-D25
A33: 공학 | B33: 0 | C33: 0 | D33: 0 | E33: 0 | F33: =SUM(B33:E33) | G33: =F33-E25
A34: 예체능 | B34: 698 | C34: 612 | D34: 722 | E34: 741 | F34: =SUM(B34:E34) | G34: =F34-F25
A36: 5. 2024 정보공시(14-라) 값과 이 시트로 계산한 값 대조
A37: 항목 | B37: 공시값 | C37: 계산값(원값) | D37: 계산값(공시 표기) | E37: 차이
A38: 입학정원 기준면적(A) | B38: 158374 | C38: =SUM(C21:C23)*12+SUM(D21:F23)*14 | D38: =ROUND(C38,0) | E38: =D38-B38
A39: 재학생 기준면적(B) | B39: 167476 | C39: =SUM(C25:C27)*12+SUM(D25:F27)*14 | D39: =ROUND(C39,0) | E39: =D39-B39
A40: 기본시설(C) | B40: 170000 | C40: =B16 | D40: =ROUND(C40,0) | E40: =D40-B40
A41: 지원시설(D) | B41: 55520 | C41: =C16 | D41: =ROUND(C41,0) | E41: =D41-B41
A42: 연구시설(E) | B42: 0 | C42: =D16 | D42: =ROUND(C42,0) | E42: =D42-B42
A43: 부속시설(교지경계선 내) | B43: 4253 | C43: =F6+F9 | D43: =ROUND(C43,0) | E43: =D43-B43
A44: 기타시설(교지경계선 내) | B44: 497 | C44: =G6+G9 | D44: =ROUND(C44,0) | E44: =D44-B44
A45: 입학정원기준 확보율(%) | B45: 142.4 | C45: =E16/C38*100 | D45: =ROUND(C45,1) | E45: =D45-B45
...
